Workbook
Name _0___Floors: #REF!
Name _1___Wall_R_Value: #REF!
Name _2___Roof_R_Value: #REF!
Name _3___Window_U_Value: #REF!
Name _4___Window_SHGC: #REF!
Name _5___WWR: #REF!
Name _6___Corridor_Ventilation: #REF!
Name _7___ERV_Efficiency: #REF!
Name Assumptions: Measures!$B$2:$G$7
Name File_Name: #REF!
Name RAW_Data: [1]!Table1[#Data]
Name RAW_Data: [1]!Table1[#Data]
Name Slicer_Air_Leakage: #N/A
Name Slicer_Controls: #N/A
Name Slicer_En_Saving: #N/A
Name Slicer_ERV: #N/A
Name Slicer_GHG_Saving: #N/A
Name Slicer_Glass_R: #N/A
Name Slicer_HVAC_System: #N/A
Name Slicer_LPD: #N/A
Name Slicer_Spandrels_R: #N/A
Name TEDI: #REF!
Name TEDI_Data: #REF!

Sheet Final
A1: Spandrels R(ft2·°F·h/BTU) | B1: Glass R(ft2·°F·h/BTU) | C1: Air Leakage | D1: LPD | E1: ERV | F1: Controls | G1: HVAC System | H1: Solar PV | I1: Electricity kWh | J1: Natural Gas kWh | K1: Total Energy kWh | L1: TEUI kWh/m² | M1: TEDI kWh/m² | N1: GHGI kgCO2/m² | O1: En Saving % | P1: GHG Saving%
A2: 5 | B2: 2.8 | C2: Current | D2: Current | E2: None | F2: Current | G2: Current | H2: No | I2: 11827263 | J2: 11604177 | K2: 23431440 | L2: 215.93843 | M2: 100.94388 | N2: 38.848358 | O2: 0 | P2: 0
A3: 5 | B3: 2.8 | C3: Current | D3: Current | E3: 0.75 | F3: Current | G3: Current | H3: No | I3: 12188438 | J3: 7677596.2 | K3: 19866034 | L3: 183.08052 | M3: 65.586922 | N3: 32.538785 | O3: 0.15216333 | P3: 0.16241543
A4: 5 | B4: 2.8 | C4: Current | D4: 0.25 | E4: None | F4: Current | G4: Current | H4: No | I4: 11303698 | J4: 11891141 | K4: 23194839 | L4: 213.75797 | M4: 103.68771 | N4: 38.530572 | O4: 0.010097576 | P4: 0.008180152
A5: 5 | B5: 2.8 | C5: Current | D5: 0.25 | E5: 0.75 | F5: Current | G5: Current | H5: No | I5: 11666316 | J5: 7972383.5 | K5: 19638700 | L5: 180.98546 | M5: 68.326646 | N5: 32.236958 | O5: 0.16186545 | P5: 0.17018479
A6: 5 | B6: 2.8 | C6: Improved | D6: Current | E6: None | F6: Current | G6: Current | H6: No | I6: 11828447 | J6: 11403970 | K6: 23232417 | L6: 214.10428 | M6: 98.976327 | N6: 38.499652 | O6: 0.0084938399 | P6: 0.0089760821
A7: 5 | B7: 2.8 | C7: Improved | D7: Current | E7: 0.75 | F7: Current | G7: Current | H7: No | I7: 12189693 | J7: 7470796.8 | K7: 19660490 | L7: 181.18627 | M7: 63.620185 | N7: 32.178647 | O7: 0.16093549 | P7: 0.17168579
A8: 5 | B8: 2.8 | C8: Improved | D8: 0.25 | E8: None | F8: Current | G8: Current | H8: No | I8: 11303910 | J8: 11684225 | K8: 22988135 | L8: 211.85303 | M8: 101.69298 | N8: 38.168595 | O8: 0.018919254 | P8: 0.017497856
A9: 5 | B9: 2.8 | C9: Improved | D9: 0.25 | E9: 0.75 | F9: Current | G9: Current | H9: No | I9: 11666718 | J9: 7766375.2 | K9: 19433093 | L9: 179.09064 | M9: 66.332676 | N9: 31.876869 | O9: 0.17064025 | P9: 0.17945389
A10: 5 | B10: 4 | C10: Current | D10: Current | E10: None | F10: Current | G10: Current | H10: No | I10: 11840697 | J10: 10787908 | K10: 22628605 | L10: 208.5397 | M10: 92.911346 | N10: 37.440123 | O10: 0.034263139 | P10: 0.036249524
A11: 5 | B11: 4 | C11: Current | D11: Current | E11: 0.75 | F11: Current | G11: Current | H11: No | I11: 12201177 | J11: 6831881 | K11: 19033058 | L11: 175.40401 | M11: 57.560607 | N11: 31.077901 | O11: 0.18771284 | P11: 0.20002021
A12: 5 | B12: 4 | C12: Current | D12: 0.25 | E12: None | F12: Current | G12: Current | H12: No | I12: 11313475 | J12: 11053923 | K12: 22367398 | L12: 206.13248 | M12: 95.517666 | N12: 37.079926 | O12: 0.045410865 | P12: 0.045521403
A13: 5 | B13: 4 | C13: Current | D13: 0.25 | E13: 0.75 | F13: Current | G13: Current | H13: No | I13: 11676213 | J13: 7115885.9 | K13: 18792099 | L13: 173.18339 | M13: 60.161418 | N13: 30.752742 | O13: 0.19799642 | P13: 0.20839017
A14: 5 | B14: 4 | C14: Improved | D14: Current | E14: None | F14: Current | G14: Current | H14: No | I14: 11843899 | J14: 10587907 | K14: 22431806 | L14: 206.72604 | M14: 90.940715 | N14: 37.094938 | O14: 0.042662103 | P14: 0.04513498
A15: 5 | B15: 4 | C15: Improved | D15: Current | E15: 0.75 | F15: Current | G15: Current | H15: No | I15: 12204443 | J15: 6622093 | K15: 18826536 | L15: 173.50075 | M15: 55.59283 | N15: 30.71568 | O15: 0.19652672 | P15: 0.20934418
A16: 5 | B16: 4 | C16: Improved | D16: 0.25 | E16: None | F16: Current | G16: Current | H16: No | I16: 11315829 | J16: 10850552 | K16: 22166381 | L16: 204.27995 | M16: 93.513092 | N16: 36.727512 | O16: 0.053989821 | P16: 0.054592929
A17: 5 | B17: 4 | C17: Improved | D17: 0.25 | E17: 0.75 | F17: Current | G17: Current | H17: No | I17: 11678725 | J17: 6907445.7 | K17: 18586171 | L17: 171.28561 | M17: 58.158732 | N17: 30.3917 | O17: 0.20678496 | P17: 0.21768379
A18: 5 | B18: 5.5 | C18: Current | D18: Current | E18: None | F18: Current | G18: Current | H18: No | I18: 11850580 | J18: 10383832 | K18: 22234412 | L18: 204.90691 | M18: 88.925816 | N18: 36.748072 | O18: 0.051086403 | P18: 0.054063701
A19: 5 | B19: 5.5 | C19: Current | D19: Current | E19: 0.75 | F19: Current | G19: Current | H19: No | I19: 12210642 | J19: 6406679.4 | K19: 18617321 | L19: 171.57268 | M19: 53.580173 | N19: 30.348204 | O19: 0.20545552 | P19: 0.21880342
A20: 5 | B20: 5.5 | C20: Current | D20: 0.25 | E20: None | F20: Current | G20: Current | H20: No | I20: 11321347 | J20: 10642932 | K20: 21964279 | L20: 202.41743 | M20: 91.447637 | N20: 36.372616 | O20: 0.062615061 | P20: 0.063728347
A21: 5 | B21: 5.5 | C21: Current | D21: 0.25 | E21: 0.75 | F21: Current | G21: Current | H21: No | I21: 11683878 | J21: 6689688.1 | K21: 18373566 | L21: 169.3263 | M21: 56.095567 | N21: 30.018481 | O21: 0.21585843 | P21: 0.22729086
A22: 5 | B22: 5.5 | C22: Improved | D22: Current | E22: None | F22: Current | G22: Current | H22: No | I22: 11855250 | J22: 10181164 | K22: 22036414 | L22: 203.08221 | M22: 86.961187 | N22: 36.400517 | O22: 0.059536507 | P22: 0.063010132
A23: 5 | B23: 5.5 | C23: Improved | D23: Current | E23: 0.75 | F23: Current | G23: Current | H23: No | I23: 12215404 | J23: 6196276.1 | K23: 18411680 | L23: 169.67754 | M23: 51.618735 | N23: 29.98725 | O23: 0.21423182 | P23: 0.22809478
A24: 5 | B24: 5.5 | C24: Improved | D24: 0.25 | E24: None | F24: Current | G24: Current | H24: No | I24: 11324809 | J24: 10440293 | K24: 21765102 | L24: 200.58186 | M24: 89.443972 | N24: 36.023221 | O24: 0.071115469 | P24: 0.072722174
A25: 5 | B25: 5.5 | C25: Improved | D25: 0.25 | E25: 0.75 | F25: Current | G25: Current | H25: No | I25: 11687454 | J25: 6475446.5 | K25: 18162901 | L25: 167.38485 | M25: 54.094332 | N25: 29.648948 | O25: 0.22484916 | P25: 0.23680306
A26: 10 | B26: 2.8 | C26: Current | D26: Current | E26: None | F26: Current | G26: Current | H26: No | I26: 11827896 | J26: 11032446 | K26: 22860342 | L26: 210.67533 | M26: 95.30417 | N26: 37.848252 | O26: 0.024373146 | P26: 0.025743828
A27: 10 | B27: 2.8 | C27: Current | D27: Current | E27: 0.75 | F27: Current | G27: Current | H27: No | I27: 12188285 | J27: 7085120.9 | K27: 19273406 | L27: 177.619 | M27: 59.949351 | N27: 31.501125 | O27: 0.17745534 | P27: 0.18912596
A28: 10 | B28: 2.8 | C28: Current | D28: 0.25 | E28: None | F28: Current | G28: Current | H28: No | I28: 11302694 | J28: 11305376 | K28: 22608070 | L28: 208.35045 | M28: 97.98464 | N28: 37.503327 | O28: 0.035139554 | P28: 0.034622576
A29: 10 | B29: 2.8 | C29: Current | D29: 0.25 | E29: 0.75 | F29: Current | G29: Current | H29: No | I29: 11665153 | J29: 7377417.7 | K29: 19042571 | L29: 175.49168 | M29: 62.625549 | N29: 31.193355 | O29: 0.18730686 | P29: 0.1970483
A30: 10 | B30: 2.8 | C30: Improved | D30: Current | E30: None | F30: Current | G30: Current | H30: No | I30: 11829221 | J30: 10831126 | K30: 22660347 | L30: 208.83222 | M30: 93.322687 | N30: 37.497818 | O30: 0.032908485 | P30: 0.034764407
A31: 10 | B31: 2.8 | C31: Improved | D31: Current | E31: 0.75 | F31: Current | G31: Current | H31: No | I31: 12189951 | J31: 6877618.3 | K31: 19067569 | L31: 175.72206 | M31: 57.969933 | N31: 31.140399 | O31: 0.18623998 | P31: 0.19841144
A32: 10 | B32: 2.8 | C32: Improved | D32: 0.25 | E32: None | F32: Current | G32: Current | H32: No | I32: 11303518 | J32: 11102034 | K32: 22405552 | L32: 206.48409 | M32: 95.971977 | N32: 37.148568 | O32: 0.043782557 | P32: 0.043754483
A33: 10 | B33: 2.8 | C33: Improved | D33: 0.25 | E33: 0.75 | F33: Current | G33: Current | H33: No | I33: 11666149 | J33: 7165871.7 | K33: 18832021 | L33: 173.5513 | M33: 60.613861 | N33: 30.8245 | O33: 0.19629265 | P33: 0.20654304
A34: 10 | B34: 4 | C34: Current | D34: Current | E34: None | F34: Current | G34: Current | H34: No | I34: 11843882 | J34: 10219195 | K34: 22063077 | L34: 203.32793 | M34: 87.295401 | N34: 36.4493 | O34: 0.058398574 | P34: 0.06175441
A35: 10 | B35: 4 | C35: Current | D35: Current | E35: 0.75 | F35: Current | G35: Current | H35: No | I35: 12203734 | J35: 6233692.2 | K35: 18437426 | L35: 169.91481 | M35: 51.950646 | N35: 30.034482 | O35: 0.21313303 | P35: 0.22687898
A36: 10 | B36: 4 | C36: Current | D36: 0.25 | E36: None | F36: Current | G36: Current | H36: No | I36: 11315082 | J36: 10480434 | K36: 21795516 | L36: 200.86215 | M36: 89.808849 | N36: 36.078268 | O36: 0.06981747 | P36: 0.071305188
A37: 10 | B37: 4 | C37: Current | D37: 0.25 | E37: 0.75 | F37: Current | G37: Current | H37: No | I37: 11677331 | J37: 6514386.2 | K37: 18191717 | L37: 167.65042 | M37: 54.456531 | N37: 29.701271 | O37: 0.22361933 | P37: 0.23545619
A38: 10 | B38: 4 | C38: Improved | D38: Current | E38: None | F38: Current | G38: Current | H38: No | I38: 11847414 | J38: 10014945 | K38: 21862359 | L38: 201.47816 | M38: 85.323401 | N38: 36.097193 | O38: 0.06696477 | P38: 0.070818049
A39: 10 | B39: 4 | C39: Improved | D39: Current | E39: 0.75 | F39: Current | G39: Current | H39: No | I39: 12207716 | J39: 6019479.9 | K39: 18227196 | L39: 167.97738 | M39: 49.982056 | N39: 29.665636 | O39: 0.22210518 | P39: 0.23637348
A40: 10 | B40: 4 | C40: Improved | D40: 0.25 | E40: None | F40: Current | G40: Current | H40: No | I40: 11318717 | J40: 10273957 | K40: 21592674 | L40: 198.99281 | M40: 87.791102 | N40: 35.722423 | O40: 0.078474304 | P40: 0.08046504
...

Sheet Raw
A1: 1 | B1: 2 | C1: 3 | D1: 4 | E1: 5 | F1: 6 | G1: 7 | H1: 8 | I1: 9 | J1: 10 | K1: 11 | L1: 12 | M1: 13 | N1: 14 | O1: 15 | P1: 16 | Q1: 17 | R1: 18 | S1: 19 | T1: 20 | U1: 21 | V1: 22 | W1: 23 | X1: 24 | Y1: 25 | Z1: 26 | AA1: 27 | AB1: 28 | AC1: 29 | AD1: 30 | AE1: 31 | AF1: 32 | AG1: 33 | AH1: 34 | AI1: 35 | AJ1: 36 | AK1: 37 | AL1: 38 | AM1: 39 | AN1: 40 | AO1: 41 | AP1: 42 | AQ1: 43 | AR1: 44 | AS1: 45 | AT1: 46 | AU1: 47 | AV1: 48 | AW1: 49 | AX1: 50 | AY1: 51 | AZ1: 52 | BA1: 53 | BB1: 54 | BC1: 55 | BD1: 56 | BE1: 57 | BF1: 58 | BG1: 59 | BH1: 60 | BI1: 61 | BJ1: 62 | BK1: 63 | BL1: 64 | BM1: 65 | BN1: 66 | BO1: 67 | BP1: 68 | BQ1: 69 | BR1: 70 | BS1: 71 | BT1: 72 | BU1: 73 | BV1: 74 | BW1: 75 | BX1: 76 | BY1: 77 | BZ1: 78 | CA1: 79 | CB1: 80
B2: Run ID | C2: HVAC System | D2: Controls | E2: File Name | F2: Run Date | G2: Gross Floor Area (ft²) | H2: Gross Volume (ft³) | I2: Gross Exterior Walls (ft²) | J2: Gross Exterior Roofs (ft²) | K2: Gross Exterior Floors (ft²) | L2: Gross Windows (ft²) | M2: Gross Skylights (ft²) | N2: Walls (MBTU) | O2: Roofs (MBTU) | P2: Interior Surface (MBTU) | Q2: Underground Surface (MBTU) | R2: Infiltration (MBTU) | S2: Window Conduction (MBTU) | T2: Window Solar (MBTU) | U2: Occupants (MBTU) | V2: Lights (MBTU) | W2: Equipment (MBTU) | X2: Source (MBTU) | Y2: Total (MBTU) | Z2: Total Heating Coil (MBTU) | AA2: Under Heated Hours | AB2: Under Cooled Hours | AC2: $ | AD2: $ | AE2: Lights (MBTU) | AF2: Task Light (MBTU) | AG2: Misc. Equip (MBTU) | AH2: Space Heating (MBTU) | AI2: Space Cooling (MBTU) | AJ2: Heat Rejection (MBTU) | AK2: Pumps & Aux (MBTU) | AL2: Ventilation Fans (MBTU) | AM2: Refrig Display (MBTU) | AN2: Heat Pump Supplimental (MBTU) | AO2: Domestic Hot Water (MBTU) | AP2: Exterior Usage (MBTU) | AQ2: Lights (MBTU) | AR2: Task Light (MBTU) | AS2: Misc. Equip (MBTU) | AT2: Space Heating (MBTU) | AU2: Space Cooling (MBTU) | AV2: Heat Rejection (MBTU) | AW2: Pumps & Aux (MBTU) | AX2: Ventilation Fans (MBTU) | AY2: Refrig Display (MBTU) | AZ2: Heat Pump Supplimental (MBTU) | BA2: Domestic Hot Water (MBTU) | BB2: Exterior Usage (MBTU) | BC2: Lights (kBTUH) | BD2: Task Light (kBTUH) | BE2: Misc. Equip (kBTUH) | BF2: Space Heating (kBTUH) | BG2: Space Cooling (kBTUH) | BH2: Heat Rejection (kBTUH) | BI2: Pumps & Aux (kBTUH) | BJ2: Ventilation Fans (kBTUH) | BK2: Refrig Display (kBTUH) | BL2: Heat Pump Supplimental (kBTUH) | BM2: Domestic Hot Water (kBTUH) | BN2: Exterior Usage (kBTUH) | BO2: Total (kBTUH) | BP2: Lights (kBTUH) | BQ2: Task Light (kBTUH) | BR2: Misc. Equip (kBTUH) | BS2: Space Heating (kBTUH) | BT2: Space Cooling (kBTUH) | BU2: Heat Rejection (kBTUH) | BV2: Pumps & Aux (kBTUH) | BW2: Ventilation Fans (kBTUH) | BX2: Refrig Display (kBTUH) | BY2: Heat Pump Supplimental (kBTUH) | BZ2: Domestic Hot Water (kBTUH) | CA2: Exterior Usage (kBTUH) | CB2: Total (kBTUH)
A3: x | B3: 1 | C3: Current | D3: Current | E3: 1AAAAA | F3: 4/29/2025 9:16:58 | G3: 1167990 | H3: 14789094 | I3: 315037.84 | J3: 174922.89 | K3: 55527.85 | L3: 186240.67 | M3: 0 | N3: -4649.082 | O3: -1111.681 | P3: 0 | Q3: -1368.584 | R3: -3177.809 | S3: -10021.72 | T3: 1318.816 | U3: 858.848 | V3: 2408.691 | W3: 3408.915 | X3: 0 | Y3: -12333.6 | Z3: -37383.625 | AA3: 16357 | AB3: 0 | AC3: 1845054 | AD3: 348125 | AE3: 7386.8492 | AF3: 0 | AG3: 10979.398 | AH3: 49.293511 | AI3: 4075.2829 | AJ3: 201.90101 | AK3: 5412.2521 | AL3: 7710.2485 | AM3: 0 | AN3: 0 | AO3: 4524.3102 | AP3: 26.549486 | AQ3: 0 | AR3: 0 | AS3: 0 | AT3: 35667.7 | AU3: 0 | AV3: 0 | AW3: 3937 | AX3: 0 | AY3: 0 | AZ3: 0 | BA3: 0 | BB3: 0 | BC3: 2048.9009 | BD3: 0 | BE3: 2890.952 | BF3: 18.051193 | BG3: 2450.3309 | BH3: 1515.3582 | BI3: 876.12962 | BJ3: 1876.6347 | BK3: 0 | BL3: 0 | BM3: 1651.7814 | BN3: 3.0307165 | BO3: 11938.269 | BP3: 0 | BQ3: 0 | BR3: 0 | BS3: 27200 | BT3: 0 | BU3: 0 | BV3: 2130 | BW3: 0 | BX3: 0 | BY3: 0 | BZ3: 0 | CA3: 0 | CB3: 28920
B4: 2 | C4: Current | D4: Current | E4: 1AAAAB | F4: 4/29/2025 9:17:00 | G4: 1167990 | H4: 14789094 | I4: 315037.84 | J4: 174922.89 | K4: 55527.85 | L4: 186240.67 | M4: 0 | N4: -4649.082 | O4: -1111.681 | P4: 0 | Q4: -1368.584 | R4: -3177.809 | S4: -10021.72 | T4: 1318.816 | U4: 858.848 | V4: 2408.691 | W4: 3408.915 | X4: 0 | Y4: -12333.6 | Z4: -24289.506 | AA4: 16352 | AB4: 0 | AC4: 1901395 | AD4: 230328 | AE4: 7386.8492 | AF4: 0 | AG4: 10979.398 | AH4: 34.344707 | AI4: 4085.73 | AJ4: 161.5836 | AK4: 5579.0814 | AL4: 8820.9174 | AM4: 0 | AN4: 0 | AO4: 4524.3102 | AP4: 26.549486 | AQ4: 0 | AR4: 0 | AS4: 0 | AT4: 25315.6 | AU4: 0 | AV4: 0 | AW4: 887.8 | AX4: 0 | AY4: 0 | AZ4: 0 | BA4: 0 | BB4: 0 | BC4: 2048.9009 | BD4: 0 | BE4: 2890.952 | BF4: 18.061432 | BG4: 1367.0306 | BH4: 696.45045 | BI4: 717.30711 | BJ4: 2027.0203 | BK4: 0 | BL4: 0 | BM4: 1651.7814 | BN4: 3.0307165 | BO4: 10524.409 | BP4: 0 | BQ4: 0 | BR4: 0 | BS4: 22950 | BT4: 0 | BU4: 0 | BV4: 820 | BW4: 0 | BX4: 0 | BY4: 0 | BZ4: 0 | CA4: 0 | CB4: 23320
B5: 3 | C5: Current | D5: Current | E5: 1AAABA | F5: 4/29/2025 9:17:02 | G5: 1167990 | H5: 14789094 | I5: 315037.84 | J5: 174922.89 | K5: 55527.85 | L5: 186240.67 | M5: 0 | N5: -4807.696 | O5: -1113.906 | P5: 0 | Q5: -1368.584 | R5: -3290.236 | S5: -10403.42 | T5: 1390.797 | U5: 950.243 | V5: 2061.176 | W5: 3707.062 | X5: 0 | Y5: -12874.56 | Z5: -38399.777 | AA5: 16451 | AB5: 0 | AC5: 1763378 | AD5: 356735 | AE5: 5731.5627 | AF5: 0 | AG5: 10979.398 | AH5: 50.494876 | AI5: 3999.5287 | AJ5: 191.65527 | AK5: 5416.0303 | AL5: 7659.6444 | AM5: 0 | AN5: 0 | AO5: 4524.3102 | AP5: 26.549486 | AQ5: 0 | AR5: 0 | AS5: 0 | AT5: 36647.1 | AU5: 0 | AV5: 0 | AW5: 3937 | AX5: 0 | AY5: 0 | AZ5: 0 | BA5: 0 | BB5: 0 | BC5: 1574.1159 | BD5: 0 | BE5: 2890.952 | BF5: 18.04778 | BG5: 2388.0749 | BH5: 1516.5767 | BI5: 874.04771 | BJ5: 1807.6961 | BK5: 0 | BL5: 0 | BM5: 1651.7814 | BN5: 3.0307165 | BO5: 11282.173 | BP5: 0 | BQ5: 0 | BR5: 0 | BS5: 27260 | BT5: 0 | BU5: 0 | BV5: 2130 | BW5: 0 | BX5: 0 | BY5: 0 | BZ5: 0 | CA5: 0 | CB5: 28980
B6: 4 | C6: Current | D6: Current | E6: 1AAABB | F6: 4/29/2025 9:17:04 | G6: 1167990 | H6: 14789094 | I6: 315037.84 | J6: 174922.89 | K6: 55527.85 | L6: 186240.67 | M6: 0 | N6: -4807.696 | O6: -1113.906 | P6: 0 | Q6: -1368.584 | R6: -3290.236 | S6: -10403.42 | T6: 1390.797 | U6: 950.243 | V6: 2061.176 | W6: 3707.062 | X6: 0 | Y6: -12874.56 | Z6: -25304.137 | AA6: 16446 | AB6: 0 | AC6: 1819947 | AD6: 239172 | AE6: 5731.5627 | AF6: 0 | AG6: 10979.398 | AH6: 35.75085 | AI6: 4014.4809 | AJ6: 150.32081 | AK6: 5583.9176 | AL6: 8770.4873 | AM6: 0 | AN6: 0 | AO6: 4524.3102 | AP6: 26.549486 | AQ6: 0 | AR6: 0 | AS6: 0 | AT6: 26321.7 | AU6: 0 | AV6: 0 | AW6: 887.8 | AX6: 0 | AY6: 0 | AZ6: 0 | BA6: 0 | BB6: 0 | BC6: 1574.1159 | BD6: 0 | BE6: 2890.952 | BF6: 18.030715 | BG6: 1301.7883 | BH6: 627.15012 | BI6: 717.16718 | BJ6: 1957.8053 | BK6: 0 | BL6: 0 | BM6: 1651.7814 | BN6: 3.0307165 | BO6: 9861.5555 | BP6: 0 | BQ6: 0 | BR6: 0 | BS6: 22980 | BT6: 0 | BU6: 0 | BV6: 820 | BW6: 0 | BX6: 0 | BY6: 0 | BZ6: 0 | CA6: 0 | CB6: 23350
B7: 5 | C7: Current | D7: Current | E7: 1AABAA | F7: 4/29/2025 9:17:06 | G7: 1167990 | H7: 14789094 | I7: 315037.84 | J7: 174922.89 | K7: 55527.85 | L7: 186240.67 | M7: 0 | N7: -4595.778 | O7: -1108.99 | P7: 0 | Q7: -1368.584 | R7: -2647.677 | S7: -9885.926 | T7: 1291.173 | U7: 828.067 | V7: 2336.019 | W7: 3307.493 | X7: 0 | Y7: -11844.21 | Z7: -36654.961 | AA7: 16204 | AB7: 0 | AC7: 1845239 | AD7: 342119 | AE7: 7386.8492 | AF7: 0 | AG7: 10979.398 | AH7: 48.921498 | AI7: 4075.1805 | AJ7: 203.02387 | AK7: 5411.1839 | AL7: 7714.7093 | AM7: 0 | AN7: 0 | AO7: 4524.3102 | AP7: 26.549486 | AQ7: 0 | AR7: 0 | AS7: 0 | AT7: 34984.4 | AU7: 0 | AV7: 0 | AW7: 3937 | AX7: 0 | AY7: 0 | AZ7: 0 | BA7: 0 | BB7: 0 | BC7: 2048.9009 | BD7: 0 | BE7: 2890.952 | BF7: 18.030715 | BG7: 2436.0408 | BH7: 1515.3582 | BI7: 875.17058 | BJ7: 1881.4606 | BK7: 0 | BL7: 0 | BM7: 1651.7814 | BN7: 3.0307165 | BO7: 11928.453 | BP7: 0 | BQ7: 0 | BR7: 0 | BS7: 26620 | BT7: 0 | BU7: 0 | BV7: 2130 | BW7: 0 | BX7: 0 | BY7: 0 | BZ7: 0 | CA7: 0 | CB7: 28270
B8: 6 | C8: Current | D8: Current | E8: 1AABAB | F8: 4/29/2025 9:17:08 | G8: 1167990 | H8: 14789094 | I8: 315037.84 | J8: 174922.89 | K8: 55527.85 | L8: 186240.67 | M8: 0 | N8: -4595.778 | O8: -1108.99 | P8: 0 | Q8: -1368.584 | R8: -2647.677 | S8: -9885.926 | T8: 1291.173 | U8: 828.067 | V8: 2336.019 | W8: 3307.493 | X8: 0 | Y8: -11844.21 | Z8: -23561.143 | AA8: 16199 | AB8: 0 | AC8: 1901592 | AD8: 224124 | AE8: 7386.8492 | AF8: 0 | AG8: 10979.398 | AH8: 33.573376 | AI8: 4087.0986 | AJ8: 162.22866 | AK8: 5577.45 | AL8: 8825.5897 | AM8: 0 | AN8: 0 | AO8: 4524.3102 | AP8: 26.549486 | AQ8: 0 | AR8: 0 | AS8: 0 | AT8: 24609.8 | AU8: 0 | AV8: 0 | AW8: 887.8 | AX8: 0 | AY8: 0 | AZ8: 0 | BA8: 0 | BB8: 0 | BC8: 2048.9009 | BD8: 0 | BE8: 2890.952 | BF8: 18.023889 | BG8: 1352.5357 | BH8: 684.12964 | BI8: 717.00335 | BJ8: 2031.8667 | BK8: 0 | BL8: 0 | BM8: 1651.7814 | BN8: 3.0307165 | BO8: 10513.835 | BP8: 0 | BQ8: 0 | BR8: 0 | BS8: 22810 | BT8: 0 | BU8: 0 | BV8: 820 | BW8: 0 | BX8: 0 | BY8: 0 | BZ8: 0 | CA8: 0 | CB8: 23180
B9: 7 | C9: Current | D9: Current | E9: 1AABBA | F9: 4/29/2025 9:17:10 | G9: 1167990 | H9: 14789094 | I9: 315037.84 | J9: 174922.89 | K9: 55527.85 | L9: 186240.67 | M9: 0 | N9: -4757.098 | O9: -1111.448 | P9: 0 | Q9: -1368.584 | R9: -2743.786 | S9: -10273.39 | T9: 1361.822 | U9: 918.716 | V9: 2004.662 | W9: 3602.113 | X9: 0 | Y9: -12366.99 | Z9: -37661.047 | AA9: 16288 | AB9: 0 | AC9: 1763412 | AD9: 350527 | AE9: 5731.5627 | AF9: 0 | AG9: 10979.398 | AH9: 49.798631 | AI9: 3998.655 | AJ9: 192.51193 | AK9: 5414.6753 | AL9: 7662.4362 | AM9: 0 | AN9: 0 | AO9: 4524.3102 | AP9: 26.549486 | AQ9: 0 | AR9: 0 | AS9: 0 | AT9: 35940.9 | AU9: 0 | AV9: 0 | AW9: 3937 | AX9: 0 | AY9: 0 | AZ9: 0 | BA9: 0 | BB9: 0 | BC9: 1574.1159 | BD9: 0 | BE9: 2890.952 | BF9: 18.017063 | BG9: 2374.9554 | BH9: 1498.9282 | BI9: 873.13645 | BJ9: 1812.3923 | BK9: 0 | BL9: 0 | BM9: 1651.7814 | BN9: 3.0307165 | BO9: 11274.006 | BP9: 0 | BQ9: 0 | BR9: 0 | BS9: 26990 | BT9: 0 | BU9: 0 | BV9: 2130 | BW9: 0 | BX9: 0 | BY9: 0 | BZ9: 0 | CA9: 0 | CB9: 28710
B10: 8 | C10: Current | D10: Current | E10: 1AABBB | F10: 4/29/2025 9:17:11 | G10: 1167990 | H10: 14789094 | I10: 315037.84 | J10: 174922.89 | K10: 55527.85 | L10: 186240.67 | M10: 0 | N10: -4757.098 | O10: -1111.448 | P10: 0 | Q10: -1368.584 | R10: -2743.786 | S10: -10273.39 | T10: 1361.822 | U10: 918.716 | V10: 2004.662 | W10: 3602.113 | X10: 0 | Y10: -12366.99 | Z10: -24565.689 | AA10: 16283 | AB10: 0 | AC10: 1820010 | AD10: 232992 | AE10: 5731.5627 | AF10: 0 | AG10: 10979.398 | AH10: 35.102386 | AI10: 4014.7949 | AJ10: 151.09896 | AK10: 5581.9688 | AL10: 8773.3645 | AM10: 0 | AN10: 0 | AO10: 4524.3102 | AP10: 26.549486 | AQ10: 0 | AR10: 0 | AS10: 0 | AT10: 25618.6 | AU10: 0 | AV10: 0 | AW10: 887.8 | AX10: 0 | AY10: 0 | AZ10: 0 | BA10: 0 | BB10: 0 | BC10: 1574.1159 | BD10: 0 | BE10: 2890.952 | BF10: 18.054606 | BG10: 1288.0852 | BH10: 616.2252 | BI10: 716.87366 | BJ10: 1962.5084 | BK10: 0 | BL10: 0 | BM10: 1651.7814 | BN10: 3.0307165 | BO10: 9853.1971 | BP10: 0 | BQ10: 0 | BR10: 0 | BS10: 22850 | BT10: 0 | BU10: 0 | BV10: 820 | BW10: 0 | BX10: 0 | BY10: 0 | BZ10: 0 | CA10: 0 | CB10: 23210
B11: 9 | C11: Current | D11: Current | E11: 1ABAAA | F11: 4/29/2025 9:17:13 | G11: 1167990 | H11: 14789094 | I11: 315037.84 | J11: 174922.89 | K11: 55527.85 | L11: 186240.67 | M11: 0 | N11: -4309.447 | O11: -1108.517 | P11: 0 | Q11: -1368.584 | R11: -2898.095 | S11: -6715.244 | T11: 1107.69 | U11: 681.33 | V11: 1973.182 | W11: 2791.834 | X11: 0 | Y11: -9845.851 | Z11: -34408.852 | AA11: 16095 | AB11: 0 | AC11: 1847149 | AD11: 323638 | AE11: 7386.8492 | AF11: 0 | AG11: 10979.398 | AH11: 47.658699 | AI11: 4094.9621 | AJ11: 208.31056 | AK11: 5407.317 | AL11: 7736.5796 | AM11: 0 | AN11: 0 | AO11: 4524.3102 | AP11: 26.549486 | AQ11: 0 | AR11: 0 | AS11: 0 | AT11: 32881.8 | AU11: 0 | AV11: 0 | AW11: 3937 | AX11: 0 | AY11: 0 | AZ11: 0 | BA11: 0 | BB11: 0 | BC11: 2048.9009 | BD11: 0 | BE11: 2890.952 | BF11: 17.979521 | BG11: 2453.522 | BH11: 1515.3582 | BI11: 876.23201 | BJ11: 1902.6142 | BK11: 0 | BL11: 0 | BM11: 1651.7814 | BN11: 3.0307165 | BO11: 12003.139 | BP11: 0 | BQ11: 0 | BR11: 0 | BS11: 25800 | BT11: 0 | BU11: 0 | BV11: 2130 | BW11: 0 | BX11: 0 | BY11: 0 | BZ11: 0 | CA11: 0 | CB11: 27520
B12: 10 | C12: Current | D12: Current | E12: 1ABAAB | F12: 4/29/2025 9:17:15 | G12: 1167990 | H12: 14789094 | I12: 315037.84 | J12: 174922.89 | K12: 55527.85 | L12: 186240.67 | M12: 0 | N12: -4309.447 | O12: -1108.517 | P12: 0 | Q12: -1368.584 | R12: -2898.095 | S12: -6715.244 | T12: 1107.69 | U12: 681.33 | V12: 1973.182 | W12: 2791.834 | X12: 0 | Y12: -9845.851 | Z12: -21317.035 | AA12: 16093 | AB12: 0 | AC12: 1903385 | AD12: 204957 | AE12: 7386.8492 | AF12: 0 | AG12: 10979.398 | AH12: 31.63481 | AI12: 4107.2488 | AJ12: 167.45732 | AK12: 5571.5388 | AL12: 8847.2552 | AM12: 0 | AN12: 0 | AO12: 4524.3102 | AP12: 26.549486 | AQ12: 0 | AR12: 0 | AS12: 0 | AT12: 22429.2 | AU12: 0 | AV12: 0 | AW12: 887.8 | AX12: 0 | AY12: 0 | AZ12: 0 | BA12: 0 | BB12: 0 | BC12: 2048.9009 | BD12: 0 | BE12: 2890.952 | BF12: 18.020476 | BG12: 1371.5323 | BH12: 701.87366 | BI12: 716.46752 | BJ12: 2053.1773 | BK12: 0 | BL12: 0 | BM12: 1651.7814 | BN12: 3.0307165 | BO12: 10592.525 | BP12: 0 | BQ12: 0 | BR12: 0 | BS12: 22340 | BT12: 0 | BU12: 0 | BV12: 820 | BW12: 0 | BX12: 0 | BY12: 0 | BZ12: 0 | CA12: 0 | CB12: 22700
B13: 11 | C13: Current | D13: Current | E13: 1ABABA | F13: 4/29/2025 9:17:17 | G13: 1167990 | H13: 14789094 | I13: 315037.84 | J13: 174922.89 | K13: 55527.85 | L13: 186240.67 | M13: 0 | N13: -4495.643 | O13: -1111.085 | P13: 0 | Q13: -1368.584 | R13: -3031.79 | S13: -7048.75 | T13: 1175.832 | U13: 774.124 | V13: 1735.96 | W13: 3092.879 | X13: 0 | Y13: -10277.06 | Z13: -35374.078 | AA13: 16167 | AB13: 0 | AC13: 1764904 | AD13: 331618 | AE13: 5731.5627 | AF13: 0 | AG13: 10979.398 | AH13: 48.348119 | AI13: 4014.5492 | AJ13: 196.6348 | AK13: 5410.4978 | AL13: 7680.6922 | AM13: 0 | AN13: 0 | AO13: 4524.3102 | AP13: 26.549486 | AQ13: 0 | AR13: 0 | AS13: 0 | AT13: 33789.7 | AU13: 0 | AV13: 0 | AW13: 3937 | AX13: 0 | AY13: 0 | AZ13: 0 | BA13: 0 | BB13: 0 | BC13: 1574.1159 | BD13: 0 | BE13: 2890.952 | BF13: 18.034128 | BG13: 2391.1397 | BH13: 1521.0988 | BI13: 874.13986 | BJ13: 1832.7405 | BK13: 0 | BL13: 0 | BM13: 1651.7814 | BN13: 3.0307165 | BO13: 11343.197 | BP13: 0 | BQ13: 0 | BR13: 0 | BS13: 25860 | BT13: 0 | BU13: 0 | BV13: 2130 | BW13: 0 | BX13: 0 | BY13: 0 | BZ13: 0 | CA13: 0 | CB13: 27580
B14: 12 | C14: Current | D14: Current | E14: 1ABABB | F14: 4/29/2025 9:17:19 | G14: 1167990 | H14: 14789094 | I14: 315037.84 | J14: 174922.89 | K14: 55527.85 | L14: 186240.67 | M14: 0 | N14: -4495.643 | O14: -1111.085 | P14: 0 | Q14: -1368.584 | R14: -3031.79 | S14: -7048.75 | T14: 1175.832 | U14: 774.124 | V14: 1735.96 | W14: 3092.879 | X14: 0 | Y14: -10277.06 | Z14: -22280.221 | AA14: 16166 | AB14: 0 | AC14: 1821491 | AD14: 213477 | AE14: 5731.5627 | AF14: 0 | AG14: 10979.398 | AH14: 32.931738 | AI14: 4032.2556 | AJ14: 155.83275 | AK14: 5576.0268 | AL14: 8791.6887 | AM14: 0 | AN14: 0 | AO14: 4524.3102 | AP14: 26.549486 | AQ14: 0 | AR14: 0 | AS14: 0 | AT14: 23398.5 | AU14: 0 | AV14: 0 | AW14: 887.8 | AX14: 0 | AY14: 0 | AZ14: 0 | BA14: 0 | BB14: 0 | BC14: 1574.1159 | BD14: 0 | BE14: 2890.952 | BF14: 18.051193 | BG14: 1305.0682 | BH14: 632.13305 | BI14: 716.31735 | BJ14: 1982.9384 | BK14: 0 | BL14: 0 | BM14: 1651.7814 | BN14: 3.0307165 | BO14: 9924.8729 | BP14: 0 | BQ14: 0 | BR14: 0 | BS14: 22390 | BT14: 0 | BU14: 0 | BV14: 820 | BW14: 0 | BX14: 0 | BY14: 0 | BZ14: 0 | CA14: 0 | CB14: 22750
B15: 13 | C15: Current | D15: Current | E15: 1ABBAA | F15: 4/29/2025 9:17:21 | G15: 1167990 | H15: 14789094 | I15: 315037.84 | J15: 174922.89 | K15: 55527.85 | L15: 186240.67 | M15: 0 | N15: -4243.205 | O15: -1104.798 | P15: 0 | Q15: -1368.584 | R15: -2400.513 | S15: -6592.154 | T15: 1079.972 | U15: 649.019 | V15: 1896.283 | W15: 2684.943 | X15: 0 | Y15: -9399.036 | Z15: -33679.047 | AA15: 15965 | AB15: 0 | AC15: 1847648 | AD15: 317638 | AE15: 7386.8492 | AF15: 0 | AG15: 10979.398 | AH15: 47.409552 | AI15: 4097.7232 | AJ15: 209.91807 | AK15: 5406.0371 | AL15: 7744.6683 | AM15: 0 | AN15: 0 | AO15: 4524.3102 | AP15: 26.549486 | AQ15: 0 | AR15: 0 | AS15: 0 | AT15: 32199.2 | AU15: 0 | AV15: 0 | AW15: 3937 | AX15: 0 | AY15: 0 | AZ15: 0 | BA15: 0 | BB15: 0 | BC15: 2048.9009 | BD15: 0 | BE15: 2890.952 | BF15: 18.04778 | BG15: 2439.2421 | BH15: 1515.3582 | BI15: 875.43337 | BJ15: 1907.5357 | BK15: 0 | BL15: 0 | BM15: 1651.7814 | BN15: 3.0307165 | BO15: 11993.245 | BP15: 0 | BQ15: 0 | BR15: 0 | BS15: 25530 | BT15: 0 | BU15: 0 | BV15: 2130 | BW15: 0 | BX15: 0 | BY15: 0 | BZ15: 0 | CA15: 0 | CB15: 27250
... B74: 72 | C74: Current | D74: Current | E74: 1CCBBB | F74: 4/29/2025 9:19:16 | G74: 1167990 | H74: 14789094 | I74: 315037.84 | J74: 174922.89 | K74: 55527.85 | L74: 186240.67 | M74: 0 | N74: -1870.439 | O74: -1101.627 | P74: 0 | Q74: -1368.584 | R74: -2119.507 | S74: -4764.581 | T74: 853.58 | U74: 490.148 | V74: 1209.543 | W74: 2099.54 | X74: 0 | Y74: -6571.928 | Z74: -17203.277 | AA74: 15634 | AB74: 0 | AC74: 1823888 | AD74: 169368 | AE74: 5731.5627 | AF74: 0 | AG74: 10979.398 | AH74: 27.525595 | AI74: 4063.4024 | AJ74: 164.14333 | AK74: 5563.1565 | AL74: 8822.9686 | AM74: 0 | AN74: 0 | AO74: 4524.3102 | AP74: 26.549486 | AQ74: 0 | AR74: 0 | AS74: 0 | AT74: 18380.4 | AU74: 0 | AV74: 0 | AW74: 887.8 | AX74: 0 | AY74: 0 | AZ74: 0 | BA74: 0 | BB74: 0 | BC74: 1574.1159 | BD74: 0 | BE74: 2890.952 | BF74: 17.986347 | BG74: 1293.8873 | BH74: 646.70302 | BI74: 712.42656 | BJ74: 1994.4674 | BK74: 0 | BL74: 0 | BM74: 1651.7814 | BN74: 3.0307165 | BO74: 9952.5828 | BP74: 0 | BQ74: 0 | BR74: 0 | BS74: 20320 | BT74: 0 | BU74: 0 | BV74: 820 | BW74: 0 | BX74: 0 | BY74: 0 | BZ74: 0 | CA74: 0 | CB74: 20690
A75: x | B75: 73 | C75: Current | D75: Improved | E75: 1AAAAA | F75: 4/29/2025 9:16:54 | G75: 1167990 | H75: 14789094 | I75: 315037.84 | J75: 174922.89 | K75: 55527.85 | L75: 186240.67 | M75: 0 | N75: -4649.082 | O75: -1111.681 | P75: 0 | Q75: -1368.584 | R75: -3177.809 | S75: -10021.72 | T75: 1318.816 | U75: 858.848 | V75: 2408.691 | W75: 3408.915 | X75: 0 | Y75: -12333.6 | Z75: -32212.334 | AA75: 14894 | AB75: 0 | AC75: 1662998 | AD75: 293468 | AE75: 7386.8492 | AF75: 0 | AG75: 10979.398 | AH75: 47.525593 | AI75: 3661.8802 | AJ75: 171.47439 | AK75: 3494.7028 | AL75: 6080.962 | AM75: 0 | AN75: 0 | AO75: 4533.7198 | AP75: 26.549486 | AQ75: 0 | AR75: 0 | AS75: 0 | AT75: 29813.2 | AU75: 0 | AV75: 0 | AW75: 3573.5 | AX75: 0 | AY75: 0 | AZ75: 0 | BA75: 0 | BB75: 0 | BC75: 2048.9009 | BD75: 0 | BE75: 2890.952 | BF75: 18.027302 | BG75: 2407.5698 | BH75: 1543.2763 | BI75: 535.31054 | BJ75: 1813.836 | BK75: 0 | BL75: 0 | BM75: 1651.7814 | BN75: 3.0307165 | BO75: 11529.136 | BP75: 0 | BQ75: 0 | BR75: 0 | BS75: 27240 | BT75: 0 | BU75: 0 | BV75: 2130 | BW75: 0 | BX75: 0 | BY75: 0 | BZ75: 0 | CA75: 0 | CB75: 28960
B76: 74 | C76: Current | D76: Improved | E76: 1AAAAB | F76: 4/29/2025 9:16:56 | G76: 1167990 | H76: 14789094 | I76: 315037.84 | J76: 174922.89 | K76: 55527.85 | L76: 186240.67 | M76: 0 | N76: -4649.082 | O76: -1111.681 | P76: 0 | Q76: -1368.584 | R76: -3177.809 | S76: -10021.72 | T76: 1318.816 | U76: 858.848 | V76: 2408.691 | W76: 3408.915 | X76: 0 | Y76: -12333.6 | Z76: -20365.758 | AA76: 14890 | AB76: 0 | AC76: 1715219 | AD76: 188230 | AE76: 7386.8492 | AF76: 0 | AG76: 10979.398 | AH76: 33.805458 | AI76: 3685.4058 | AJ76: 137.1877 | AK76: 3659.5628 | AL76: 7083.1223 | AM76: 0 | AN76: 0 | AO76: 4533.7198 | AP76: 26.549486 | AQ76: 0 | AR76: 0 | AS76: 0 | AT76: 20608.7 | AU76: 0 | AV76: 0 | AW76: 805.5 | AX76: 0 | AY76: 0 | AZ76: 0 | BA76: 0 | BB76: 0 | BC76: 2048.9009 | BD76: 0 | BE76: 2890.952 | BF76: 18.051193 | BG76: 1328.2217 | BH76: 660.65182 | BI76: 469.83955 | BJ76: 1958.3514 | BK76: 0 | BL76: 0 | BM76: 1651.7814 | BN76: 3.0307165 | BO76: 10177.061 | BP76: 0 | BQ76: 0 | BR76: 0 | BS76: 22970 | BT76: 0 | BU76: 0 | BV76: 820 | BW76: 0 | BX76: 0 | BY76: 0 | BZ76: 0 | CA76: 0 | CB76: 23330
B77: 75 | C77: Current | D77: Improved | E77: 1AAABA | F77: 4/29/2025 9:16:57 | G77: 1167990 | H77: 14789094 | I77: 315037.84 | J77: 174922.89 | K77: 55527.85 | L77: 186240.67 | M77: 0 | N77: -4807.696 | O77: -1113.906 | P77: 0 | Q77: -1368.584 | R77: -3290.236 | S77: -10403.42 | T77: 1390.797 | U77: 950.243 | V77: 2061.176 | W77: 3707.062 | X77: 0 | Y77: -12874.56 | Z77: -33228.461 | AA77: 14988 | AB77: 0 | AC77: 1581018 | AD77: 302080 | AE77: 5731.5627 | AF77: 0 | AG77: 10979.398 | AH77: 48.747436 | AI77: 3587.7983 | AJ77: 161.01023 | AK77: 3490.3649 | AL77: 6030.3647 | AM77: 0 | AN77: 0 | AO77: 4533.7198 | AP77: 26.549486 | AQ77: 0 | AR77: 0 | AS77: 0 | AT77: 30792.9 | AU77: 0 | AV77: 0 | AW77: 3573.5 | AX77: 0 | AY77: 0 | AZ77: 0 | BA77: 0 | BB77: 0 | BC77: 1574.1159 | BD77: 0 | BE77: 2890.952 | BF77: 18.023889 | BG77: 2345.6005 | BH77: 1458.6142 | BI77: 532.98289 | BJ77: 1746.7951 | BK77: 0 | BL77: 0 | BM77: 1651.7814 | BN77: 3.0307165 | BO77: 10874.518 | BP77: 0 | BQ77: 0 | BR77: 0 | BS77: 27300 | BT77: 0 | BU77: 0 | BV77: 2130 | BW77: 0 | BX77: 0 | BY77: 0 | BZ77: 0 | CA77: 0 | CB77: 29020
B78: 76 | C78: Current | D78: Improved | E78: 1AAABB | F78: 4/29/2025 9:16:59 | G78: 1167990 | H78: 14789094 | I78: 315037.84 | J78: 174922.89 | K78: 55527.85 | L78: 186240.67 | M78: 0 | N78: -4807.696 | O78: -1113.906 | P78: 0 | Q78: -1368.584 | R78: -3290.236 | S78: -10403.42 | T78: 1390.797 | U78: 950.243 | V78: 2061.176 | W78: 3707.062 | X78: 0 | Y78: -12874.56 | Z78: -21380.381 | AA78: 14984 | AB78: 0 | AC78: 1633294 | AD78: 197043 | AE78: 5731.5627 | AF78: 0 | AG78: 10979.398 | AH78: 35.238905 | AI78: 3611.9144 | AJ78: 126.12627 | AK78: 3655.9758 | AL78: 7032.6922 | AM78: 0 | AN78: 0 | AO78: 4533.7198 | AP78: 26.549486 | AQ78: 0 | AR78: 0 | AS78: 0 | AT78: 21611.3 | AU78: 0 | AV78: 0 | AW78: 805.5 | AX78: 0 | AY78: 0 | AZ78: 0 | BA78: 0 | BB78: 0 | BC78: 1574.1159 | BD78: 0 | BE78: 2890.952 | BF78: 18.04778 | BG78: 1264.1535 | BH78: 593.06821 | BI78: 469.15354 | BJ78: 1891.5527 | BK78: 0 | BL78: 0 | BM78: 1651.7814 | BN78: 3.0307165 | BO78: 9517.2108 | BP78: 0 | BQ78: 0 | BR78: 0 | BS78: 23000 | BT78: 0 | BU78: 0 | BV78: 820 | BW78: 0 | BX78: 0 | BY78: 0 | BZ78: 0 | CA78: 0 | CB78: 23360
B79: 77 | C79: Current | D79: Improved | E79: 1AABAA | F79: 4/29/2025 9:17:01 | G79: 1167990 | H79: 14789094 | I79: 315037.84 | J79: 174922.89 | K79: 55527.85 | L79: 186240.67 | M79: 0 | N79: -4595.778 | O79: -1108.99 | P79: 0 | Q79: -1368.584 | R79: -2647.677 | S79: -9885.926 | T79: 1291.173 | U79: 828.067 | V79: 2336.019 | W79: 3307.493 | X79: 0 | Y79: -11844.21 | Z79: -31483.686 | AA79: 14741 | AB79: 0 | AC79: 1663094 | AD79: 287462 | AE79: 7386.8492 | AF79: 0 | AG79: 10979.398 | AH79: 47.156993 | AI79: 3660.2284 | AJ79: 172.66893 | AK79: 3493.1601 | AL79: 6085.4329 | AM79: 0 | AN79: 0 | AO79: 4533.7198 | AP79: 26.549486 | AQ79: 0 | AR79: 0 | AS79: 0 | AT79: 29129.9 | AU79: 0 | AV79: 0 | AW79: 3573.5 | AX79: 0 | AY79: 0 | AZ79: 0 | BA79: 0 | BB79: 0 | BC79: 2048.9009 | BD79: 0 | BE79: 2890.952 | BF79: 18.068258 | BG79: 2393.8394 | BH79: 1523.8053 | BI79: 534.76787 | BJ79: 1822.4504 | BK79: 0 | BL79: 0 | BM79: 1651.7814 | BN79: 3.0307165 | BO79: 11519.962 | BP79: 0 | BQ79: 0 | BR79: 0 | BS79: 26690 | BT79: 0 | BU79: 0 | BV79: 2130 | BW79: 0 | BX79: 0 | BY79: 0 | BZ79: 0 | CA79: 0 | CB79: 28340
B80: 78 | C80: Current | D80: Improved | E80: 1AABAB | F80: 4/29/2025 9:17:03 | G80: 1167990 | H80: 14789094 | I80: 315037.84 | J80: 174922.89 | K80: 55527.85 | L80: 186240.67 | M80: 0 | N80: -4595.778 | O80: -1108.99 | P80: 0 | Q80: -1368.584 | R80: -2647.677 | S80: -9885.926 | T80: 1291.173 | U80: 828.067 | V80: 2336.019 | W80: 3307.493 | X80: 0 | Y80: -11844.21 | Z80: -19637.393 | AA80: 14737 | AB80: 0 | AC80: 1715394 | AD80: 182006 | AE80: 7386.8492 | AF80: 0 | AG80: 10979.398 | AH80: 33.044366 | AI80: 3686.4468 | AJ80: 138.12286 | AK80: 3657.4673 | AL80: 7087.8219 | AM80: 0 | AN80: 0 | AO80: 4533.7198 | AP80: 26.549486 | AQ80: 0 | AR80: 0 | AS80: 0 | AT80: 19900.6 | AU80: 0 | AV80: 0 | AW80: 805.5 | AX80: 0 | AY80: 0 | AZ80: 0 | BA80: 0 | BB80: 0 | BC80: 2048.9009 | BD80: 0 | BE80: 2890.952 | BF80: 18.037541 | BG80: 1314.6449 | BH80: 648.71326 | BI80: 469.41976 | BJ80: 1966.9862 | BK80: 0 | BL80: 0 | BM80: 1651.7814 | BN80: 3.0307165 | BO80: 10167.255 | BP80: 0 | BQ80: 0 | BR80: 0 | BS80: 22830 | BT80: 0 | BU80: 0 | BV80: 820 | BW80: 0 | BX80: 0 | BY80: 0 | BZ80: 0 | CA80: 0 | CB80: 23190
B81: 79 | C81: Current | D81: Improved | E81: 1AABBA | F81: 4/29/2025 9:17:05 | G81: 1167990 | H81: 14789094 | I81: 315037.84 | J81: 174922.89 | K81: 55527.85 | L81: 186240.67 | M81: 0 | N81: -4757.098 | O81: -1111.448 | P81: 0 | Q81: -1368.584 | R81: -2743.786 | S81: -10273.39 | T81: 1361.822 | U81: 918.716 | V81: 2004.662 | W81: 3602.113 | X81: 0 | Y81: -12366.99 | Z81: -32489.775 | AA81: 14825 | AB81: 0 | AC81: 1580935 | AD81: 295886 | AE81: 5731.5627 | AF81: 0 | AG81: 10979.398 | AH81: 48.037539 | AI81: 3584.9963 | AJ81: 161.56654 | AK81: 3488.6755 | AL81: 6033.1531 | AM81: 0 | AN81: 0 | AO81: 4533.7198 | AP81: 26.549486 | AQ81: 0 | AR81: 0 | AS81: 0 | AT81: 30088.3 | AU81: 0 | AV81: 0 | AW81: 3573.5 | AX81: 0 | AY81: 0 | AZ81: 0 | BA81: 0 | BB81: 0 | BC81: 1574.1159 | BD81: 0 | BE81: 2890.952 | BF81: 18.04778 | BG81: 2332.7029 | BH81: 1441.034 | BI81: 532.47777 | BJ81: 1755.0988 | BK81: 0 | BL81: 0 | BM81: 1651.7814 | BN81: 3.0307165 | BO81: 10866.996 | BP81: 0 | BQ81: 0 | BR81: 0 | BS81: 27030 | BT81: 0 | BU81: 0 | BV81: 2130 | BW81: 0 | BX81: 0 | BY81: 0 | BZ81: 0 | CA81: 0 | CB81: 28750
B82: 80 | C82: Current | D82: Improved | E82: 1AABBB | F82: 4/29/2025 9:17:07 | G82: 1167990 | H82: 14789094 | I82: 315037.84 | J82: 174922.89 | K82: 55527.85 | L82: 186240.67 | M82: 0 | N82: -4757.098 | O82: -1111.448 | P82: 0 | Q82: -1368.584 | R82: -2743.786 | S82: -10273.39 | T82: 1361.822 | U82: 918.716 | V82: 2004.662 | W82: 3602.113 | X82: 0 | Y82: -12366.99 | Z82: -20641.926 | AA82: 14821 | AB82: 0 | AC82: 1633328 | AD82: 190879 | AE82: 5731.5627 | AF82: 0 | AG82: 10979.398 | AH82: 34.587028 | AI82: 3611.9314 | AJ82: 126.81569 | AK82: 3653.7574 | AL82: 7035.5864 | AM82: 0 | AN82: 0 | AO82: 4533.7198 | AP82: 26.549486 | AQ82: 0 | AR82: 0 | AS82: 0 | AT82: 20910 | AU82: 0 | AV82: 0 | AW82: 805.5 | AX82: 0 | AY82: 0 | AZ82: 0 | BA82: 0 | BB82: 0 | BC82: 1574.1159 | BD82: 0 | BE82: 2890.952 | BF82: 18.034128 | BG82: 1250.761 | BH82: 582.43681 | BI82: 468.73375 | BJ82: 1899.8224 | BK82: 0 | BL82: 0 | BM82: 1651.7814 | BN82: 3.0307165 | BO82: 9509.5419 | BP82: 0 | BQ82: 0 | BR82: 0 | BS82: 22860 | BT82: 0 | BU82: 0 | BV82: 820 | BW82: 0 | BX82: 0 | BY82: 0 | BZ82: 0 | CA82: 0 | CB82: 23230
B83: 81 | C83: Current | D83: Improved | E83: 1ABAAA | F83: 4/29/2025 9:17:09 | G83: 1167990 | H83: 14789094 | I83: 315037.84 | J83: 174922.89 | K83: 55527.85 | L83: 186240.67 | M83: 0 | N83: -4309.447 | O83: -1108.517 | P83: 0 | Q83: -1368.584 | R83: -2898.095 | S83: -6715.244 | T83: 1107.69 | U83: 681.33 | V83: 1973.182 | W83: 2791.834 | X83: 0 | Y83: -9845.851 | Z83: -29237.557 | AA83: 14632 | AB83: 0 | AC83: 1664883 | AD83: 268953 | AE83: 7386.8492 | AF83: 0 | AG83: 10979.398 | AH83: 45.883955 | AI83: 3675.4741 | AJ83: 178.27644 | AK83: 3490.8495 | AL83: 6107.3135 | AM83: 0 | AN83: 0 | AO83: 4533.7198 | AP83: 26.549486 | AQ83: 0 | AR83: 0 | AS83: 0 | AT83: 27024.1 | AU83: 0 | AV83: 0 | AW83: 3573.5 | AX83: 0 | AY83: 0 | AZ83: 0 | BA83: 0 | BB83: 0 | BC83: 2048.9009 | BD83: 0 | BE83: 2890.952 | BF83: 18.01365 | BG83: 2410.9179 | BH83: 1547.2593 | BI83: 535.49142 | BJ83: 1853.249 | BK83: 0 | BL83: 0 | BM83: 1651.7814 | BN83: 3.0307165 | BO83: 11593.033 | BP83: 0 | BQ83: 0 | BR83: 0 | BS83: 25820 | BT83: 0 | BU83: 0 | BV83: 2130 | BW83: 0 | BX83: 0 | BY83: 0 | BZ83: 0 | CA83: 0 | CB83: 27550
B84: 82 | C84: Current | D84: Improved | E84: 1ABAAB | F84: 4/29/2025 9:17:10 | G84: 1167990 | H84: 14789094 | I84: 315037.84 | J84: 174922.89 | K84: 55527.85 | L84: 186240.67 | M84: 0 | N84: -4309.447 | O84: -1108.517 | P84: 0 | Q84: -1368.584 | R84: -2898.095 | S84: -6715.244 | T84: 1107.69 | U84: 681.33 | V84: 1973.182 | W84: 2791.834 | X84: 0 | Y84: -9845.851 | Z84: -17393.246 | AA84: 14631 | AB84: 0 | AC84: 1717280 | AD84: 162841 | AE84: 7386.8492 | AF84: 0 | AG84: 10979.398 | AH84: 31.068257 | AI84: 3706.4263 | AJ84: 144.03412 | AK84: 3653.126 | AL84: 7109.4841 | AM84: 0 | AN84: 0 | AO84: 4533.7198 | AP84: 26.549486 | AQ84: 0 | AR84: 0 | AS84: 0 | AT84: 17720.3 | AU84: 0 | AV84: 0 | AW84: 805.5 | AX84: 0 | AY84: 0 | AZ84: 0 | BA84: 0 | BB84: 0 | BC84: 2048.9009 | BD84: 0 | BE84: 2890.952 | BF84: 18.051193 | BG84: 1333.232 | BH84: 665.94875 | BI84: 468.46754 | BJ84: 1998.0613 | BK84: 0 | BL84: 0 | BM84: 1651.7814 | BN84: 3.0307165 | BO84: 10243.876 | BP84: 0 | BQ84: 0 | BR84: 0 | BS84: 22350 | BT84: 0 | BU84: 0 | BV84: 820 | BW84: 0 | BX84: 0 | BY84: 0 | BZ84: 0 | CA84: 0 | CB84: 22720
B85: 83 | C85: Current | D85: Improved | E85: 1ABABA | F85: 4/29/2025 9:17:12 | G85: 1167990 | H85: 14789094 | I85: 315037.84 | J85: 174922.89 | K85: 55527.85 | L85: 186240.67 | M85: 0 | N85: -4495.643 | O85: -1111.085 | P85: 0 | Q85: -1368.584 | R85: -3031.79 | S85: -7048.75 | T85: 1175.832 | U85: 774.124 | V85: 1735.96 | W85: 3092.879 | X85: 0 | Y85: -10277.06 | Z85: -30202.85 | AA85: 14704 | AB85: 0 | AC85: 1582327 | AD85: 276941 | AE85: 5731.5627 | AF85: 0 | AG85: 10979.398 | AH85: 46.566549 | AI85: 3596.6516 | AJ85: 166.23207 | AK85: 3486.027 | AL85: 6051.4125 | AM85: 0 | AN85: 0 | AO85: 4533.7198 | AP85: 26.549486 | AQ85: 0 | AR85: 0 | AS85: 0 | AT85: 27932.9 | AU85: 0 | AV85: 0 | AW85: 3573.5 | AX85: 0 | AY85: 0 | AZ85: 0 | BA85: 0 | BB85: 0 | BC85: 1574.1159 | BD85: 0 | BE85: 2890.952 | BF85: 18.034128 | BG85: 2348.6517 | BH85: 1462.7678 | BI85: 533.15013 | BJ85: 1784.662 | BK85: 0 | BL85: 0 | BM85: 1651.7814 | BN85: 3.0307165 | BO85: 10934.62 | BP85: 0 | BQ85: 0 | BR85: 0 | BS85: 25890 | BT85: 0 | BU85: 0 | BV85: 2130 | BW85: 0 | BX85: 0 | BY85: 0 | BZ85: 0 | CA85: 0 | CB85: 27610
B86: 84 | C86: Current | D86: Improved | E86: 1ABABB | F86: 4/29/2025 9:17:14 | G86: 1167990 | H86: 14789094 | I86: 315037.84 | J86: 174922.89 | K86: 55527.85 | L86: 186240.67 | M86: 0 | N86: -4495.643 | O86: -1111.085 | P86: 0 | Q86: -1368.584 | R86: -3031.79 | S86: -7048.75 | T86: 1175.832 | U86: 774.124 | V86: 1735.96 | W86: 3092.879 | X86: 0 | Y86: -10277.06 | Z86: -18356.477 | AA86: 14704 | AB86: 0 | AC86: 1634879 | AD86: 171377 | AE86: 5731.5627 | AF86: 0 | AG86: 10979.398 | AH86: 32.402728 | AI86: 3629.2215 | AJ86: 131.64504 | AK86: 3649.4195 | AL86: 7053.9209 | AM86: 0 | AN86: 0 | AO86: 4533.7198 | AP86: 26.549486 | AQ86: 0 | AR86: 0 | AS86: 0 | AT86: 18691.4 | AU86: 0 | AV86: 0 | AW86: 805.5 | AX86: 0 | AY86: 0 | AZ86: 0 | BA86: 0 | BB86: 0 | BC86: 1574.1159 | BD86: 0 | BE86: 2890.952 | BF86: 18.037541 | BG86: 1267.3787 | BH86: 597.89415 | BI86: 467.77471 | BJ86: 1929.2934 | BK86: 0 | BL86: 0 | BM86: 1651.7814 | BN86: 3.0307165 | BO86: 9579.1937 | BP86: 0 | BQ86: 0 | BR86: 0 | BS86: 22400 | BT86: 0 | BU86: 0 | BV86: 820 | BW86: 0 | BX86: 0 | BY86: 0 | BZ86: 0 | CA86: 0 | CB86: 22770
B87: 85 | C87: Current | D87: Improved | E87: 1ABBAA | F87: 4/29/2025 9:17:16 | G87: 1167990 | H87: 14789094 | I87: 315037.84 | J87: 174922.89 | K87: 55527.85 | L87: 186240.67 | M87: 0 | N87: -4243.205 | O87: -1104.798 | P87: 0 | Q87: -1368.584 | R87: -2400.513 | S87: -6592.154 | T87: 1079.972 | U87: 649.019 | V87: 1896.283 | W87: 2684.943 | X87: 0 | Y87: -9399.036 | Z87: -28507.744 | AA87: 14502 | AB87: 0 | AC87: 1665301 | AD87: 262964 | AE87: 7386.8492 | AF87: 0 | AG87: 10979.398 | AH87: 45.627983 | AI87: 3676.7915 | AJ87: 179.76449 | AK87: 3489.3512 | AL87: 6115.4193 | AM87: 0 | AN87: 0 | AO87: 4533.7198 | AP87: 26.549486 | AQ87: 0 | AR87: 0 | AS87: 0 | AT87: 26342.8 | AU87: 0 | AV87: 0 | AW87: 3573.5 | AX87: 0 | AY87: 0 | AZ87: 0 | BA87: 0 | BB87: 0 | BC87: 2048.9009 | BD87: 0 | BE87: 2890.952 | BF87: 18.078497 | BG87: 2397.2114 | BH87: 1528.2763 | BI87: 535.02726 | BJ87: 1862.133 | BK87: 0 | BL87: 0 | BM87: 1651.7814 | BN87: 3.0307165 | BO87: 11583.818 | BP87: 0 | BQ87: 0 | BR87: 0 | BS87: 25560 | BT87: 0 | BU87: 0 | BV87: 2130 | BW87: 0 | BX87: 0 | BY87: 0 | BZ87: 0 | CA87: 0 | CB87: 27280
... B146: 144 | C146: Current | D146: Improved | E146: 1CCBBB | F146: 4/29/2025 9:19:13 | G146: 1167990 | H146: 14789094 | I146: 315037.84 | J146: 174922.89 | K146: 55527.85 | L146: 186240.67 | M146: 0 | N146: -1870.439 | O146: -1101.627 | P146: 0 | Q146: -1368.584 | R146: -2119.507 | S146: -4764.581 | T146: 853.58 | U146: 490.148 | V146: 1209.543 | W146: 2099.54 | X146: 0 | Y146: -6571.928 | Z146: -13279.52 | AA146: 14172 | AB146: 0 | AC146: 1637154 | AD146: 127260 | AE146: 5731.5627 | AF146: 0 | AG146: 10979.398 | AH146: 26.965868 | AI146: 3655.8188 | AJ146: 139.69282 | AK146: 3638.7164 | AL146: 7085.2042 | AM146: 0 | AN146: 0 | AO146: 4533.7198 | AP146: 26.549486 | AQ146: 0 | AR146: 0 | AS146: 0 | AT146: 13672.3 | AU146: 0 | AV146: 0 | AW146: 805.5 | AX146: 0 | AY146: 0 | AZ146: 0 | BA146: 0 | BB146: 0 | BC146: 1574.1159 | BD146: 0 | BE146: 2890.952 | BF146: 18.020476 | BG146: 1256.505 | BH146: 604.38903 | BI146: 462.34808 | BJ146: 1954.423 | BK146: 0 | BL146: 0 | BM146: 1651.7814 | BN146: 3.0307165 | BO146: 9607.0982 | BP146: 0 | BQ146: 0 | BR146: 0 | BS146: 20350 | BT146: 0 | BU146: 0 | BV146: 820 | BW146: 0 | BX146: 0 | BY146: 0 | BZ146: 0 | CA146: 0 | CB146: 20720
A147: x | B147: 145 | C147: ASHP | D147: Improved | E147: 1AAAAA | F147: 4/29/2025 9:17:02 | G147: 1167990 | H147: 14789094 | I147: 315037.84 | J147: 174922.89 | K147: 55527.85 | L147: 186240.67 | M147: 0 | N147: -4649.082 | O147: -1111.681 | P147: 0 | Q147: -1368.584 | R147: -3177.809 | S147: -10021.72 | T147: 1318.816 | U147: 858.848 | V147: 2408.691 | W147: 3408.915 | X147: 0 | Y147: -12333.6 | Z147: -31414.166 | AA147: 18888 | AB147: 17 | AC147: 2144127 | AD147: 75792 | AE147: 7386.8492 | AF147: 0 | AG147: 10979.398 | AH147: 10468.73 | AI147: 3885.3819 | AJ147: 92.546067 | AK147: 3439.0065 | AL147: 6097.0234 | AM147: 0 | AN147: 0 | AO147: 4533.7198 | AP147: 26.549486 | AQ147: 0 | AR147: 0 | AS147: 0 | AT147: 8622.5 | AU147: 0 | AV147: 0 | AW147: 0 | AX147: 0 | AY147: 0 | AZ147: 0 | BA147: 0 | BB147: 0 | BC147: 2048.9009 | BD147: 0 | BE147: 2890.952 | BF147: 4001.4434 | BG147: 1448.0442 | BH147: 870.56648 | BI147: 480.20133 | BJ147: 1849.2729 | BK147: 0 | BL147: 0 | BM147: 1651.7814 | BN147: 3.0307165 | BO147: 12865.521 | BP147: 0 | BQ147: 0 | BR147: 0 | BS147: 33210 | BT147: 0 | BU147: 0 | BV147: 0 | BW147: 0 | BX147: 0 | BY147: 0 | BZ147: 0 | CA147: 0 | CB147: 33210
B148: 146 | C148: ASHP | D148: Improved | E148: 1AAAAB | F148: 4/29/2025 9:17:04 | G148: 1167990 | H148: 14789094 | I148: 315037.84 | J148: 174922.89 | K148: 55527.85 | L148: 186240.67 | M148: 0 | N148: -4649.082 | O148: -1111.681 | P148: 0 | Q148: -1368.584 | R148: -3177.809 | S148: -10021.72 | T148: 1318.816 | U148: 858.848 | V148: 2408.691 | W148: 3408.915 | X148: 0 | Y148: -12333.6 | Z148: -20375.576 | AA148: 15171 | AB148: 0 | AC148: 2013841 | AD148: 56650 | AE148: 7386.8492 | AF148: 0 | AG148: 10979.398 | AH148: 6478.3066 | AI148: 3927.6584 | AJ148: 62.027299 | AK148: 3622.2625 | AL148: 7042.0711 | AM148: 0 | AN148: 0 | AO148: 4533.7198 | AP148: 26.549486 | AQ148: 0 | AR148: 0 | AS148: 0 | AT148: 6444.8 | AU148: 0 | AV148: 0 | AW148: 0 | AX148: 0 | AY148: 0 | AZ148: 0 | BA148: 0 | BB148: 0 | BC148: 2048.9009 | BD148: 0 | BE148: 2890.952 | BF148: 4001.5901 | BG148: 1264.1978 | BH148: 810.8873 | BI148: 459.80542 | BJ148: 1951.8599 | BK148: 0 | BL148: 0 | BM148: 1651.7814 | BN148: 3.0307165 | BO148: 13003.589 | BP148: 0 | BQ148: 0 | BR148: 0 | BS148: 29610 | BT148: 0 | BU148: 0 | BV148: 0 | BW148: 0 | BX148: 0 | BY148: 0 | BZ148: 0 | CA148: 0 | CB148: 29610
B149: 147 | C149: ASHP | D149: Improved | E149: 1AAABA | F149: 4/29/2025 9:17:06 | G149: 1167990 | H149: 14789094 | I149: 315037.84 | J149: 174922.89 | K149: 55527.85 | L149: 186240.67 | M149: 0 | N149: -4807.696 | O149: -1113.906 | P149: 0 | Q149: -1368.584 | R149: -3290.236 | S149: -10403.42 | T149: 1390.797 | U149: 950.243 | V149: 2061.176 | W149: 3707.062 | X149: 0 | Y149: -12874.56 | Z149: -32400.09 | AA149: 19988 | AB149: 6 | AC149: 2077614 | AD149: 76823 | AE149: 5731.5627 | AF149: 0 | AG149: 10979.398 | AH149: 10815.258 | AI149: 3807.812 | AJ149: 84.194532 | AK149: 3431.01 | AL149: 6044.5456 | AM149: 0 | AN149: 0 | AO149: 4533.7198 | AP149: 26.549486 | AQ149: 0 | AR149: 0 | AS149: 0 | AT149: 8739.9 | AU149: 0 | AV149: 0 | AW149: 0 | AX149: 0 | AY149: 0 | AZ149: 0 | BA149: 0 | BB149: 0 | BC149: 1574.1159 | BD149: 0 | BE149: 2890.952 | BF149: 4001.4604 | BG149: 1445.0613 | BH149: 871.23884 | BI149: 474.47778 | BJ149: 1744.6961 | BK149: 0 | BL149: 0 | BM149: 1651.7814 | BN149: 3.0307165 | BO149: 12344.439 | BP149: 0 | BQ149: 0 | BR149: 0 | BS149: 33590 | BT149: 0 | BU149: 0 | BV149: 0 | BW149: 0 | BX149: 0 | BY149: 0 | BZ149: 0 | CA149: 0 | CB149: 33590
B150: 148 | C150: ASHP | D150: Improved | E150: 1AAABB | F150: 4/29/2025 9:17:08 | G150: 1167990 | H150: 14789094 | I150: 315037.84 | J150: 174922.89 | K150: 55527.85 | L150: 186240.67 | M150: 0 | N150: -4807.696 | O150: -1113.906 | P150: 0 | Q150: -1368.584 | R150: -3290.236 | S150: -10403.42 | T150: 1390.797 | U150: 950.243 | V150: 2061.176 | W150: 3707.062 | X150: 0 | Y150: -12874.56 | Z150: -21387.9 | AA150: 15300 | AB150: 0 | AC150: 1949453 | AD150: 57275 | AE150: 5731.5627 | AF150: 0 | AG150: 10979.398 | AH150: 6862.8766 | AI150: 3856.5662 | AJ150: 53.839586 | AK150: 3614.184 | AL150: 6991.4056 | AM150: 0 | AN150: 0 | AO150: 4533.7198 | AP150: 26.549486 | AQ150: 0 | AR150: 0 | AS150: 0 | AT150: 6515.9 | AU150: 0 | AV150: 0 | AW150: 0 | AX150: 0 | AY150: 0 | AZ150: 0 | BA150: 0 | BB150: 0 | BC150: 1574.1159 | BD150: 0 | BE150: 2890.952 | BF150: 4001.5116 | BG150: 1193.2388 | BH150: 764.52212 | BI150: 456.67573 | BJ150: 1885.0647 | BK150: 0 | BL150: 0 | BM150: 1651.7814 | BN150: 3.0307165 | BO150: 12500.746 | BP150: 0 | BQ150: 0 | BR150: 0 | BS150: 29670 | BT150: 0 | BU150: 0 | BV150: 0 | BW150: 0 | BX150: 0 | BY150: 0 | BZ150: 0 | CA150: 0 | CB150: 29670
B151: 149 | C151: ASHP | D151: Improved | E151: 1AABAA | F151: 4/29/2025 9:17:10 | G151: 1167990 | H151: 14789094 | I151: 315037.84 | J151: 174922.89 | K151: 55527.85 | L151: 186240.67 | M151: 0 | N151: -4595.778 | O151: -1108.99 | P151: 0 | Q151: -1368.584 | R151: -2647.677 | S151: -9885.926 | T151: 1291.173 | U151: 828.067 | V151: 2336.019 | W151: 3307.493 | X151: 0 | Y151: -11844.21 | Z151: -30744.932 | AA151: 17729 | AB151: 18 | AC151: 2133988 | AD151: 74458 | AE151: 7386.8492 | AF151: 0 | AG151: 10979.398 | AH151: 10243.753 | AI151: 3886.2045 | AJ151: 93.341289 | AK151: 3438.1021 | AL151: 6099.4671 | AM151: 0 | AN151: 0 | AO151: 4533.7198 | AP151: 26.549486 | AQ151: 0 | AR151: 0 | AS151: 0 | AT151: 8470.7 | AU151: 0 | AV151: 0 | AW151: 0 | AX151: 0 | AY151: 0 | AZ151: 0 | BA151: 0 | BB151: 0 | BC151: 2048.9009 | BD151: 0 | BE151: 2890.952 | BF151: 4001.5457 | BG151: 1446.2217 | BH151: 873.05112 | BI151: 477.89075 | BJ151: 1851.9316 | BK151: 0 | BL151: 0 | BM151: 1651.7814 | BN151: 3.0307165 | BO151: 12841.327 | BP151: 0 | BQ151: 0 | BR151: 0 | BS151: 32530 | BT151: 0 | BU151: 0 | BV151: 0 | BW151: 0 | BX151: 0 | BY151: 0 | BZ151: 0 | CA151: 0 | CB151: 32530
B152: 150 | C152: ASHP | D152: Improved | E152: 1AABAB | F152: 4/29/2025 9:17:11 | G152: 1167990 | H152: 14789094 | I152: 315037.84 | J152: 174922.89 | K152: 55527.85 | L152: 186240.67 | M152: 0 | N152: -4595.778 | O152: -1108.99 | P152: 0 | Q152: -1368.584 | R152: -2647.677 | S152: -9885.926 | T152: 1291.173 | U152: 828.067 | V152: 2336.019 | W152: 3307.493 | X152: 0 | Y152: -11844.21 | Z152: -19646.307 | AA152: 14946 | AB152: 0 | AC152: 2001583 | AD152: 55912 | AE152: 7386.8492 | AF152: 0 | AG152: 10979.398 | AH152: 6205.2179 | AI152: 3928.5389 | AJ152: 62.450507 | AK152: 3621.4502 | AL152: 7046.4704 | AM152: 0 | AN152: 0 | AO152: 4533.7198 | AP152: 26.549486 | AQ152: 0 | AR152: 0 | AS152: 0 | AT152: 6360.9 | AU152: 0 | AV152: 0 | AW152: 0 | AX152: 0 | AY152: 0 | AZ152: 0 | BA152: 0 | BB152: 0 | BC152: 2048.9009 | BD152: 0 | BE152: 2890.952 | BF152: 4001.5628 | BG152: 1251.8054 | BH152: 774.50847 | BI152: 458.55628 | BJ152: 1960.4981 | BK152: 0 | BL152: 0 | BM152: 1651.7814 | BN152: 3.0307165 | BO152: 13002.228 | BP152: 0 | BQ152: 0 | BR152: 0 | BS152: 29330 | BT152: 0 | BU152: 0 | BV152: 0 | BW152: 0 | BX152: 0 | BY152: 0 | BZ152: 0 | CA152: 0 | CB152: 29330
B153: 151 | C153: ASHP | D153: Improved | E153: 1AABBA | F153: 4/29/2025 9:17:13 | G153: 1167990 | H153: 14789094 | I153: 315037.84 | J153: 174922.89 | K153: 55527.85 | L153: 186240.67 | M153: 0 | N153: -4757.098 | O153: -1111.448 | P153: 0 | Q153: -1368.584 | R153: -2743.786 | S153: -10273.39 | T153: 1361.822 | U153: 918.716 | V153: 2004.662 | W153: 3602.113 | X153: 0 | Y153: -12366.99 | Z153: -31697.168 | AA153: 18591 | AB153: 6 | AC153: 2066121 | AD153: 75712 | AE153: 5731.5627 | AF153: 0 | AG153: 10979.398 | AH153: 10568.054 | AI153: 3802.8666 | AJ153: 84.791802 | AK153: 3430.1465 | AL153: 6045.4773 | AM153: 0 | AN153: 0 | AO153: 4533.7198 | AP153: 26.549486 | AQ153: 0 | AR153: 0 | AS153: 0 | AT153: 8613.4 | AU153: 0 | AV153: 0 | AW153: 0 | AX153: 0 | AY153: 0 | AZ153: 0 | BA153: 0 | BB153: 0 | BC153: 1574.1159 | BD153: 0 | BE153: 2890.952 | BF153: 4001.4263 | BG153: 1442.8361 | BH153: 873.55624 | BI153: 471.03068 | BJ153: 1755.3207 | BK153: 0 | BL153: 0 | BM153: 1651.7814 | BN153: 3.0307165 | BO153: 12337.798 | BP153: 0 | BQ153: 0 | BR153: 0 | BS153: 33240 | BT153: 0 | BU153: 0 | BV153: 0 | BW153: 0 | BX153: 0 | BY153: 0 | BZ153: 0 | CA153: 0 | CB153: 33240
B154: 152 | C154: ASHP | D154: Improved | E154: 1AABBB | F154: 4/29/2025 9:17:15 | G154: 1167990 | H154: 14789094 | I154: 315037.84 | J154: 174922.89 | K154: 55527.85 | L154: 186240.67 | M154: 0 | N154: -4757.098 | O154: -1111.448 | P154: 0 | Q154: -1368.584 | R154: -2743.786 | S154: -10273.39 | T154: 1361.822 | U154: 918.716 | V154: 2004.662 | W154: 3602.113 | X154: 0 | Y154: -12366.99 | Z154: -20648.053 | AA154: 15060 | AB154: 0 | AC154: 1937223 | AD154: 56503 | AE154: 5731.5627 | AF154: 0 | AG154: 10979.398 | AH154: 6593.4636 | AI154: 3856.143 | AJ154: 54.242316 | AK154: 3613.3546 | AL154: 6994.1359 | AM154: 0 | AN154: 0 | AO154: 4533.7198 | AP154: 26.549486 | AQ154: 0 | AR154: 0 | AS154: 0 | AT154: 6428.1 | AU154: 0 | AV154: 0 | AW154: 0 | AX154: 0 | AY154: 0 | AZ154: 0 | BA154: 0 | BB154: 0 | BC154: 1574.1159 | BD154: 0 | BE154: 2890.952 | BF154: 4001.5389 | BG154: 1182.0955 | BH154: 774.78151 | BI154: 456.49143 | BJ154: 1893.3309 | BK154: 0 | BL154: 0 | BM154: 1651.7814 | BN154: 3.0307165 | BO154: 12499.422 | BP154: 0 | BQ154: 0 | BR154: 0 | BS154: 29390 | BT154: 0 | BU154: 0 | BV154: 0 | BW154: 0 | BX154: 0 | BY154: 0 | BZ154: 0 | CA154: 0 | CB154: 29390
B155: 153 | C155: ASHP | D155: Improved | E155: 1ABAAA | F155: 4/29/2025 9:17:17 | G155: 1167990 | H155: 14789094 | I155: 315037.84 | J155: 174922.89 | K155: 55527.85 | L155: 186240.67 | M155: 0 | N155: -4309.447 | O155: -1108.517 | P155: 0 | Q155: -1368.584 | R155: -2898.095 | S155: -6715.244 | T155: 1107.69 | U155: 681.33 | V155: 1973.182 | W155: 2791.834 | X155: 0 | Y155: -9845.851 | Z155: -28799.863 | AA155: 15962 | AB155: 20 | AC155: 2103856 | AD155: 72100 | AE155: 7386.8492 | AF155: 0 | AG155: 10979.398 | AH155: 9553.4122 | AI155: 3894.2147 | AJ155: 97.778149 | AK155: 3437.7881 | AL155: 6118.4637 | AM155: 0 | AN155: 0 | AO155: 4533.7198 | AP155: 26.549486 | AQ155: 0 | AR155: 0 | AS155: 0 | AT155: 8202.5 | AU155: 0 | AV155: 0 | AW155: 0 | AX155: 0 | AY155: 0 | AZ155: 0 | BA155: 0 | BB155: 0 | BC155: 2048.9009 | BD155: 0 | BE155: 2890.952 | BF155: 4001.5423 | BG155: 1448.5084 | BH155: 869.93167 | BI155: 477.5358 | BJ155: 1900.2456 | BK155: 0 | BL155: 0 | BM155: 1651.7814 | BN155: 3.0307165 | BO155: 12844.443 | BP155: 0 | BQ155: 0 | BR155: 0 | BS155: 32290 | BT155: 0 | BU155: 0 | BV155: 0 | BW155: 0 | BX155: 0 | BY155: 0 | BZ155: 0 | CA155: 0 | CB155: 32290
B156: 154 | C156: ASHP | D156: Improved | E156: 1ABAAB | F156: 4/29/2025 9:17:19 | G156: 1167990 | H156: 14789094 | I156: 315037.84 | J156: 174922.89 | K156: 55527.85 | L156: 186240.67 | M156: 0 | N156: -4309.447 | O156: -1108.517 | P156: 0 | Q156: -1368.584 | R156: -2898.095 | S156: -6715.244 | T156: 1107.69 | U156: 681.33 | V156: 1973.182 | W156: 2791.834 | X156: 0 | Y156: -9845.851 | Z156: -17410.645 | AA156: 14713 | AB156: 0 | AC156: 1966076 | AD156: 53062 | AE156: 7386.8492 | AF156: 0 | AG156: 10979.398 | AH156: 5385.59 | AI156: 3946.5594 | AJ156: 66.535831 | AK156: 3621.4195 | AL156: 7067.2042 | AM156: 0 | AN156: 0 | AO156: 4533.7198 | AP156: 26.549486 | AQ156: 0 | AR156: 0 | AS156: 0 | AT156: 6036.7 | AU156: 0 | AV156: 0 | AW156: 0 | AX156: 0 | AY156: 0 | AZ156: 0 | BA156: 0 | BB156: 0 | BC156: 2048.9009 | BD156: 0 | BE156: 2890.952 | BF156: 4001.6072 | BG156: 1269.7746 | BH156: 808.10573 | BI156: 460.13307 | BJ156: 1991.5664 | BK156: 0 | BL156: 0 | BM156: 1651.7814 | BN156: 3.0307165 | BO156: 12895.286 | BP156: 0 | BQ156: 0 | BR156: 0 | BS156: 28450 | BT156: 0 | BU156: 0 | BV156: 0 | BW156: 0 | BX156: 0 | BY156: 0 | BZ156: 0 | CA156: 0 | CB156: 28450
...

Sheet Processed
A17: Column1 | B17: File Name | C17: Run ID | D17: Spandrels R (ft2·°F·h/BTU) | E17: Glass R (ft2·°F·h/BTU) | F17: Air Leakage | G17: LPD | H17: ERV | I17: Controls | J17: HVAC System | K17: Solar PV | L17: Electricity kWh | M17: Natural Gas kWh | N17: Total Energy kWh | O17: TEUI kWh/m² | P17: TEDI kWh/m² | Q17: GHGI kgCO2/m² | R17: En Saving % | S17: GHG Saving%
A18: x | B18: 1AAAAA | C18: 1 | D18: =VLOOKUP(MID($B18,2,1),Table2[],2,FALSE) -> 5 | E18: =VLOOKUP(MID($B18,3,1),Table2[],3,FALSE) -> 2.8 | F18: =VLOOKUP(MID($B18,4,1),Table2[],4,FALSE) -> Current | G18: =VLOOKUP(MID($B18,5,1),Table2[],5,FALSE) -> Current | H18: =VLOOKUP(MID($B18,6,1),Table2[],6,FALSE) -> None | I18: Current | J18: Current | K18: No | L18: =SUM(Raw!AE3:AP3)*293 -> 11827263 | M18: =SUM(Raw!AQ3:BB3)*293 -> 11604177 | N18: =M18+L18 -> 23431440 | O18: =N18/Processed!$V$20 -> 215.93843 | P18: =Raw!Z3*-293/Processed!$V$20 -> 100.94388 | Q18: =((L18*Processed!$V$21)+(Table3[[#This Row],[Natural Gas kWh]]*Processed!$V$22))/Processed!$V$20 -> 38.848358 | R18: =1-(O18/Processed!$V$23) -> 0 | S18: =1-(Processed!Q18/Processed!$V$24) -> 0
B19: 1AAAAB | C19: 2 | D19: =VLOOKUP(MID($B19,2,1),Table2[],2,FALSE) -> 5 | E19: =VLOOKUP(MID($B19,3,1),Table2[],3,FALSE) -> 2.8 | F19: =VLOOKUP(MID($B19,4,1),Table2[],4,FALSE) -> Current | G19: =VLOOKUP(MID($B19,5,1),Table2[],5,FALSE) -> Current | H19: =VLOOKUP(MID($B19,6,1),Table2[],6,FALSE) -> 0.75 | I19: Current | J19: Current | K19: No | L19: =SUM(Raw!AE4:AP4)*293 -> 12188438 | M19: =SUM(Raw!AQ4:BB4)*293 -> 7677596.2 | N19: =M19+L19 -> 19866034 | O19: =N19/Processed!$V$20 -> 183.08052 | P19: =Raw!Z4*-293/Processed!$V$20 -> 65.586922 | Q19: =((L19*Processed!$V$21)+(Table3[[#This Row],[Natural Gas kWh]]*Processed!$V$22))/Processed!$V$20 -> 32.538785 | R19: =1-(O19/Processed!$V$23) -> 0.15216333 | S19: =1-(Processed!Q19/Processed!$V$24) -> 0.16241543 | V19: m²
B20: 1AAABA | C20: 3 | D20: =VLOOKUP(MID($B20,2,1),Table2[],2,FALSE) -> 5 | E20: =VLOOKUP(MID($B20,3,1),Table2[],3,FALSE) -> 2.8 | F20: =VLOOKUP(MID($B20,4,1),Table2[],4,FALSE) -> Current | G20: =VLOOKUP(MID($B20,5,1),Table2[],5,FALSE) -> 0.25 | H20: =VLOOKUP(MID($B20,6,1),Table2[],6,FALSE) -> None | I20: Current | J20: Current | K20: No | L20: =SUM(Raw!AE5:AP5)*293 -> 11303698 | M20: =SUM(Raw!AQ5:BB5)*293 -> 11891141 | N20: =M20+L20 -> 23194839 | O20: =N20/Processed!$V$20 -> 213.75797 | P20: =Raw!Z5*-293/Processed!$V$20 -> 103.68771 | Q20: =((L20*Processed!$V$21)+(Table3[[#This Row],[Natural Gas kWh]]*Processed!$V$22))/Processed!$V$20 -> 38.530572 | R20: =1-(O20/Processed!$V$23) -> 0.010097576 | S20: =1-(Processed!Q20/Processed!$V$24) -> 0.008180152 | U20: Area | V20: 108509.82
B21: 1AAABB | C21: 4 | D21: =VLOOKUP(MID($B21,2,1),Table2[],2,FALSE) -> 5 | E21: =VLOOKUP(MID($B21,3,1),Table2[],3,FALSE) -> 2.8 | F21: =VLOOKUP(MID($B21,4,1),Table2[],4,FALSE) -> Current | G21: =VLOOKUP(MID($B21,5,1),Table2[],5,FALSE) -> 0.25 | H21: =VLOOKUP(MID($B21,6,1),Table2[],6,FALSE) -> 0.75 | I21: Current | J21: Current | K21: No | L21: =SUM(Raw!AE6:AP6)*293 -> 11666316 | M21: =SUM(Raw!AQ6:BB6)*293 -> 7972383.5 | N21: =M21+L21 -> 19638700 | O21: =N21/Processed!$V$20 -> 180.98546 | P21: =Raw!Z6*-293/Processed!$V$20 -> 68.326646 | Q21: =((L21*Processed!$V$21)+(Table3[[#This Row],[Natural Gas kWh]]*Processed!$V$22))/Processed!$V$20 -> 32.236958 | R21: =1-(O21/Processed!$V$23) -> 0.16186545 | S21: =1-(Processed!Q21/Processed!$V$24) -> 0.17018479 | U21: GHGI - Electricity | V21: 0.17 | W21: 2030
B22: 1AABAA | C22: 5 | D22: =VLOOKUP(MID($B22,2,1),Table2[],2,FALSE) -> 5 | E22: =VLOOKUP(MID($B22,3,1),Table2[],3,FALSE) -> 2.8 | F22: =VLOOKUP(MID($B22,4,1),Table2[],4,FALSE) -> Improved | G22: =VLOOKUP(MID($B22,5,1),Table2[],5,FALSE) -> Current | H22: =VLOOKUP(MID($B22,6,1),Table2[],6,FALSE) -> None | I22: Current | J22: Current | K22: No | L22: =SUM(Raw!AE7:AP7)*293 -> 11828447 | M22: =SUM(Raw!AQ7:BB7)*293 -> 11403970 | N22: =M22+L22 -> 23232417 | O22: =N22/Processed!$V$20 -> 214.10428 | P22: =Raw!Z7*-293/Processed!$V$20 -> 98.976327 | Q22: =((L22*Processed!$V$21)+(Table3[[#This Row],[Natural Gas kWh]]*Processed!$V$22))/Processed!$V$20 -> 38.499652 | R22: =1-(O22/Processed!$V$23) -> 0.0084938399 | S22: =1-(Processed!Q22/Processed!$V$24) -> 0.0089760821 | U22: GHGI - Natural Gas | V22: 0.19 | W22: 2030
